#VRML_SIM R2023b utf8

EXTERNPROTO "https://raw.githubusercontent.com/cyberbotics/webots/R2023b/projects/objects/backgrounds/protos/TexturedBackground.proto"
EXTERNPROTO "https://raw.githubusercontent.com/cyberbotics/webots/R2023b/projects/objects/backgrounds/protos/TexturedBackgroundLight.proto"
EXTERNPROTO "https://raw.githubusercontent.com/cyberbotics/webots/R2023b/projects/objects/floors/protos/Floor.proto"

WorldInfo {
  basicTimeStep 16
}
Viewpoint {
  orientation 0.3552231104160413 0.17767159190174675 -0.9177414381281104 2.3557081227446957
  position 0.8234809944820207 1.0562728392112335 1.1652463096984857
}
TexturedBackground {
}
TexturedBackgroundLight {
}
Floor {
  size 1 1
  tileSize 0.3 0.3
}
DEF WALL_ONE Solid {
  translation 0 -0.5 0.05
  children [
    DEF WALL_SHAPE Shape {
      appearance PBRAppearance {
        baseColor 0.109804 0.443137 0.847059
        roughness 0.5
        metalness 0
      }
      geometry Box {
        size 1 0.01 0.1
      }
    }
  ]
  name "solid(1)"
  boundingObject Box {
    size 0.1 0.1 0.1
  }
}
DEF WALL_TWO Solid {
  translation 0 0.5 0.05
  children [
    USE WALL_SHAPE
  ]
  name "solid(2)"
  boundingObject USE WALL_SHAPE
}
DEF WALL_THREE Solid {
  translation 0.5 1.83656e-06 0.05
  rotation 0 0 1 1.5708
  children [
    USE WALL_SHAPE
  ]
  name "solid(3)"
  boundingObject USE WALL_SHAPE
}
DEF WALL_FOUR Solid {
  translation -0.5 -1.83656e-06 0.05
  rotation 0 0 1 1.5708
  children [
    USE WALL_SHAPE
  ]
  name "solid(4)"
  boundingObject USE WALL_SHAPE
}
Robot {
  translation 0 0 0.05
  children [
    DistanceSensor {
      translation 0.1 0.03 0
      rotation 0 0 1 0.3
      children [
        DEF SENSOR Shape {
          appearance PBRAppearance {
            baseColor 0.101961 0.372549 0.705882
            metalness 0
          }
          geometry Box {
            size 0.01 0.01 0.01
          }
        }
      ]
      name "ds_left"
    }
    DistanceSensor {
      translation 0.1 -0.03 0
      rotation 0 0 1 -0.3
      children [
        USE SENSOR
      ]
      name "ds_right"
    }
    DEF CAR_BODY Shape {
      appearance PBRAppearance {
        baseColor 0.878431 0.105882 0.141176
        metalness 0
      }
      geometry Box {
        size 0.2 0.1 0.05
      }
    }
    HingeJoint {
      jointParameters HingeJointParameters {
        axis 0 1 0
        anchor 0.05 0.06 0
      }
      device [
        RotationalMotor {
          name "wheel0"
        }
      ]
      endPoint DEF WHEEL1 Solid {
        translation 0.05 0.06 0
        rotation 1 0 0 1.5707996938995714
        children [
          DEF WHEEL Shape {
            appearance PBRAppearance {
              baseColor 0.964706 0.827451 0.176471
              metalness 0
            }
            geometry Cylinder {
              height 0.02
              radius 0.04
              subdivision 24
            }
          }
        ]
        boundingObject USE WHEEL
        physics DEF WHEEL_PH Physics {
        }
      }
    }
    DEF WHEEL2 HingeJoint {
      jointParameters HingeJointParameters {
        axis 0 1 0
        anchor -0.05 0.06 0
      }
      device [
        RotationalMotor {
          name "wheel1"
        }
      ]
      endPoint Solid {
        translation -0.05000000001576792 0.06000000000181905 1.9581845757005774e-06
        rotation 1 7.850449076788099e-17 7.850449076788099e-17 1.5707996938995736
        children [
          USE WHEEL
        ]
        name "solid(1)"
        boundingObject USE WHEEL
        physics USE WHEEL_PH
      }
    }
    DEF WHEEL3 HingeJoint {
      jointParameters HingeJointParameters {
        axis 0 1 0
        anchor 0.05 -0.06 0
      }
      device [
        RotationalMotor {
          name "wheel2"
        }
      ]
      endPoint Solid {
        translation 0.04999999998429344 -0.06000000000217917 1.9736596831923525e-06
        rotation 0.9999999999999999 5.082627160259162e-13 5.119519834492018e-13 1.570799999993151
        children [
          USE WHEEL
        ]
        name "solid(2)"
        boundingObject USE WHEEL
        physics USE WHEEL_PH
      }
    }
    DEF WHEEL4 HingeJoint {
      jointParameters HingeJointParameters {
        axis 0 1 0
        anchor -0.05 -0.06 0
      }
      device [
        RotationalMotor {
          name "wheel3"
        }
      ]
      endPoint Solid {
        translation -0.05 -0.06 0
        rotation 0.9999999999999999 0 0 1.5707999999931548
        children [
          USE WHEEL
        ]
        name "solid(3)"
        boundingObject USE WHEEL
        physics USE WHEEL_PH
      }
    }
  ]
  boundingObject USE CAR_BODY
  physics Physics {
    density -1
    mass 1
  }
}
